<?xml version="1.0" encoding="utf-8"?>
<!-- This URDF was automatically created by SolidWorks to URDF Exporter! Originally created by Stephen Brawner (brawner@gmail.com) 
     Commit Version: 1.6.0-4-g7f85cfe  Build Version: 1.6.7995.38578
     For more information, please see http://wiki.ros.org/sw_urdf_exporter -->
<robot
  name="alicia_duo_descriptions">
  <link
    name="base_link">
    <visual>
      <origin
        xyz="0 0 0"
        rpy="0 0 0" />
      <geometry>
        <mesh
          filename="package://alicia_duo_descriptions/meshes/base_link.STL" />
      </geometry>
      <material
        name="">
        <color
          rgba="1 1 1 1" />
      </material>
    </visual>
    <collision>
      <origin
        xyz="0 0 0"
        rpy="0 0 0" />
      <geometry>
        <mesh
          filename="package://alicia_duo_descriptions/meshes/base_link.STL" />
      </geometry>
    </collision>
  </link>
  <link
    name="Link1">
    <inertial>
      <origin
        xyz="7.1808E-05 0.00011331 0.054988"
        rpy="0 0 0" />
      <mass
        value="0.1961" />
      <inertia
        ixx="0.00025127"
        ixy="2.4433E-07"
        ixz="7.4121E-08"
        iyy="0.00012563"
        iyz="4.1559E-08"
        izz="0.00031522" />
    </inertial>
    <visual>
      <origin
        xyz="0 0 0"
        rpy="0 0 0" />
      <geometry>
        <mesh
          filename="package://alicia_duo_descriptions/meshes/Link1.STL" />
      </geometry>
      <material
        name="">
        <color
          rgba="1 1 1 1" />
      </material>
    </visual>
    <collision>
      <origin
        xyz="0 0 0"
        rpy="0 0 0" />
      <geometry>
        <mesh
          filename="package://alicia_duo_descriptions/meshes/Link1.STL" />
      </geometry>
    </collision>
  </link>
  <joint
    name="Joint1"
    type="revolute">
    <origin
      xyz="0 0 0.0745"
      rpy="0 0 0" />
    <parent
      link="base_link" />
    <child
      link="Link1" />
    <axis
      xyz="0 0 1" />
    <limit
      lower="-2.16"
      upper="2.16"
      effort="12"
      velocity="5" />
  </joint>
  <link
    name="Link2">
    <inertial>
      <origin
        xyz="0.15107 -0.014052 -5.8128E-05"
        rpy="0 0 0" />
      <mass
        value="0.21717" />
      <inertia
        ixx="0.00013186"
        ixy="5.9949E-06"
        ixz="-3.0761E-06"
        iyy="0.00021477"
        iyz="3.2832E-07"
        izz="0.00012724" />
    </inertial>
    <visual>
      <origin
        xyz="0 0 0"
        rpy="0 0 0" />
      <geometry>
        <mesh
          filename="package://alicia_duo_descriptions/meshes/Link2.STL" />
      </geometry>
      <material
        name="">
        <color
          rgba="1 1 1 1" />
      </material>
    </visual>
    <collision>
      <origin
        xyz="0 0 0"
        rpy="0 0 0" />
      <geometry>
        <mesh
          filename="package://alicia_duo_descriptions/meshes/Link2.STL" />
      </geometry>
    </collision>
  </link>
  <joint
    name="Joint2"
    type="revolute">
    <origin
      xyz="-4E-05 0 0.09361"
      rpy="-1.5708 -1.4701 0" />
    <parent
      link="Link1" />
    <child
      link="Link2" />
    <axis
      xyz="0 0 -1" />
    <limit
      lower="-3.14"
      upper="3.14"
      effort="12"
      velocity="5" />
  </joint>
  <link
    name="Link3">
    <inertial>
      <origin
        xyz="-0.00302856221408143 -0.0581994772199088 -0.00047829449592837"
        rpy="0 0 0" />
      <mass
        value="0.0865602005421272" />
      <inertia
        ixx="7.08139311465948E-05"
        ixy="-2.15530524975187E-06"
        ixz="-3.73515851249802E-07"
        iyy="2.93740492594595E-05"
        iyz="-5.06280707236989E-06"
        izz="7.53468971475965E-05" />
    </inertial>
    <visual>
      <origin
        xyz="0 0 0"
        rpy="0 0 0" />
      <geometry>
        <mesh
          filename="package://alicia_duo_descriptions/meshes/Link3.STL" />
      </geometry>
      <material
        name="">
        <color
          rgba="1 1 1 1" />
      </material>
    </visual>
    <collision>
      <origin
        xyz="0 0 0"
        rpy="0 0 0" />
      <geometry>
        <mesh
          filename="package://alicia_duo_descriptions/meshes/Link3.STL" />
      </geometry>
    </collision>
  </link>
  <joint
    name="Joint3"
    type="revolute">
    <origin
      xyz="0.22471 0 0.0004"
      rpy="0 0 -2.4569" />
    <parent
      link="Link2" />
    <child
      link="Link3" />
    <axis
      xyz="0 0 -1" />
    <limit
      lower="-3.14"
      upper="3.14"
      effort="12"
      velocity="5" />
  </joint>
  <link
    name="Link4">
    <inertial>
      <origin
        xyz="-5.08168284341082E-07 -0.00029327303500894 0.0689595985441509"
        rpy="0 0 0" />
      <mass
        value="0.0943760430662397" />
      <inertia
        ixx="2.91454313334424E-05"
        ixy="2.30645167594814E-10"
        ixz="1.14165678767118E-09"
        iyy="2.78832974647989E-05"
        iyz="-3.3816587479662E-07"
        izz="1.74699240092054E-05" />
    </inertial>
    <visual>
      <origin
        xyz="0 0 0"
        rpy="0 0 0" />
      <geometry>
        <mesh
          filename="package://alicia_duo_descriptions/meshes/Link4.STL" />
      </geometry>
      <material
        name="">
        <color
          rgba="1 1 1 1" />
      </material>
    </visual>
    <collision>
      <origin
        xyz="0 0 0"
        rpy="0 0 0" />
      <geometry>
        <mesh
          filename="package://alicia_duo_descriptions/meshes/Link4.STL" />
      </geometry>
    </collision>
  </link>
  <joint
    name="Joint4"
    type="revolute">
    <origin
      xyz="0.00211 -0.0969 -0.0005"
      rpy="1.5708 0 0" />
    <parent
      link="Link3" />
    <child
      link="Link4" />
    <axis
      xyz="0 0 -1" />
    <limit
      lower="-3.14"
      upper="3.14"
      effort="12"
      velocity="5" />
  </joint>
  <link
    name="Link5">
    <inertial>
      <origin
        xyz="-0.0117308607950611 -0.02707823363479 0.000843233457865933"
        rpy="0 0 0" />
      <mass
        value="0.0298054906363541" />
      <inertia
        ixx="1.00571793842848E-05"
        ixy="-1.33618696334041E-06"
        ixz="-1.03835147521356E-07"
        iyy="1.43226276019951E-05"
        iyz="-1.60850894178713E-07"
        izz="1.07199721232635E-05" />
    </inertial>
    <visual>
      <origin
        xyz="0 0 0"
        rpy="0 0 0" />
      <geometry>
        <mesh
          filename="package://alicia_duo_descriptions/meshes/Link5.STL" />
      </geometry>
      <material
        name="">
        <color
          rgba="1 1 1 1" />
      </material>
    </visual>
    <collision>
      <origin
        xyz="0 0 0"
        rpy="0 0 0" />
      <geometry>
        <mesh
          filename="package://alicia_duo_descriptions/meshes/Link5.STL" />
      </geometry>
    </collision>
  </link>
  <joint
    name="Joint5"
    type="revolute">
    <origin
      xyz="0.00014 0.0002 0.12011"
      rpy="-1.5708 0 0" />
    <parent
      link="Link4" />
    <child
      link="Link5" />
    <axis
      xyz="0 0 1" />
    <limit
      lower="-3.14"
      upper="3.14"
      effort="12"
      velocity="5" />
  </joint>
  <link
    name="Link6">
    <inertial>
      <origin
        xyz="-3.11347159165365E-09 6.1996621497553E-10 -0.00146275616399945"
        rpy="0 0 0" />
      <mass
        value="0.00075405362358679" />
      <inertia
        ixx="1.92367692913405E-08"
        ixy="9.19452447394752E-14"
        ixz="3.52333006367405E-15"
        iyy="1.92358360258474E-08"
        iyz="-3.90127282952403E-17"
        izz="3.70123450485907E-08" />
    </inertial>
    <visual>
      <origin
        xyz="0 0 0"
        rpy="0 0 0" />
      <geometry>
        <mesh
          filename="package://alicia_duo_descriptions/meshes/Link6.STL" />
      </geometry>
      <material
        name="">
        <color
          rgba="1 1 1 1" />
      </material>
    </visual>
    <collision>
      <origin
        xyz="0 0 0"
        rpy="0 0 0" />
      <geometry>
        <mesh
          filename="package://alicia_duo_descriptions/meshes/Link6.STL" />
      </geometry>
    </collision>
  </link>
  <joint
    name="Joint6"
    type="revolute">
    <origin
      xyz="-0.00389 -0.0592 0.00064"
      rpy="1.5708 0 0" />
    <parent
      link="Link5" />
    <child
      link="Link6" />
    <axis
      xyz="0 0 -1" />
    <limit
      lower="-3.14"
      upper="3.14"
      effort="12"
      velocity="5" />
  </joint>
  <link
    name="Grasp_base">
    <inertial>
      <origin
        xyz="-0.0011655281691727 0.000653296052045323 0.0287714514529389"
        rpy="0 0 0" />
      <mass
        value="0.0482959693358257" />
      <inertia
        ixx="5.26092663212743E-05"
        ixy="-7.51486127271044E-08"
        ixz="4.87630447298486E-07"
        iyy="1.16846563417782E-05"
        iyz="1.93051292104745E-07"
        izz="5.0903565077189E-05" />
    </inertial>
    <visual>
      <origin
        xyz="0 0 0"
        rpy="0 0 0" />
      <geometry>
        <mesh
          filename="package://alicia_duo_descriptions/meshes/Grasp_base.STL" />
      </geometry>
      <material
        name="">
        <color
          rgba="1 1 1 1" />
      </material>
    </visual>
    <collision>
      <origin
        xyz="0 0 0"
        rpy="0 0 0" />
      <geometry>
        <mesh
          filename="package://alicia_duo_descriptions/meshes/Grasp_base.STL" />
      </geometry>
    </collision>
  </link>
  <joint
    name="Joint6_to_gripper_base"
    type="fixed">
    <origin
      xyz="0 0 0"
      rpy="0 0 0" />
    <parent
      link="Link6" />
    <child
      link="Grasp_base" />
    <axis
      xyz="0 0 0" />
  </joint>
  <link
    name="Link7">
    <inertial>
      <origin
        xyz="0.00251938005470254 -0.0478416586551963 -0.00586388602065606"
        rpy="0 0 0" />
      <mass
        value="0.0298800419940728" />
      <inertia
        ixx="5.37602725468321E-06"
        ixy="4.57138780207955E-07"
        ixz="3.44618099913482E-09"
        iyy="3.83966068819012E-06"
        iyz="-5.32359727667237E-09"
        izz="7.8167142043849E-06" />
    </inertial>
    <visual>
      <origin
        xyz="0 0 0"
        rpy="0 0 0" />
      <geometry>
        <mesh
          filename="package://alicia_duo_descriptions/meshes/Link7.STL" />
      </geometry>
      <material
        name="">
        <color
          rgba="1 1 1 1" />
      </material>
    </visual>
    <collision>
      <origin
        xyz="0 0 0"
        rpy="0 0 0" />
      <geometry>
        <mesh
          filename="package://alicia_duo_descriptions/meshes/Link7.STL" />
      </geometry>
    </collision>
  </link>
  <joint
    name="left_finger"
    type="fixed">
    <origin
      xyz="-0.0065308 -0.015222 0.11382"
      rpy="1.5708 0 0" />
    <parent
      link="Grasp_base" />
    <child
      link="Link7" />
    <axis
      xyz="0 0 -1" />

  </joint>
  <link
    name="tool0">
     <visual>
      <origin
        xyz="0 0 0" 
        rpy="0 0 0" />
      <geometry>
        <sphere radius="0.005" /> <!-- 定义一个半径为0.02米的小球体 -->
      </geometry>
      <material
        name="green_virtual_sphere_material"> <!-- 可以给材质起个名字 -->
        <color
          rgba="0 1 0 1" /> <!-- 绿色 (R G B A)，A为1表示不透明 -->
      </material>
    </visual>
  </link>
  <joint
    name="Grasp2tool"
    type="fixed">
    <origin
      xyz="-0.0065308 -0.00063845 0.11382"
      rpy="0 0 0" />
    <parent
      link="Grasp_base" />
    <child
      link="tool0" />
    <axis
      xyz="0 0 0" />
  </joint>
  <link
    name="Link8">
    <inertial>
      <origin
        xyz="-0.00252444987589934 -0.0478416797997642 -0.00577908200176484"
        rpy="0 0 0" />
      <mass
        value="0.0298800419940728" />
      <inertia
        ixx="5.3760272551167E-06"
        ixy="-4.60064397458462E-07"
        ixz="3.44549357218208E-09"
        iyy="3.84255821485079E-06"
        iyz="5.32358884287877E-09"
        izz="7.81961173147026E-06" />
    </inertial>
    <visual>
      <origin
        xyz="0 0 0"
        rpy="0 0 0" />
      <geometry>
        <mesh
          filename="package://alicia_duo_descriptions/meshes/Link8.STL" />
      </geometry>
      <material
        name="">
        <color
          rgba="1 1 1 1" />
      </material>
    </visual>
    <collision>
      <origin
        xyz="0 0 0"
        rpy="0 0 0" />
      <geometry>
        <mesh
          filename="package://alicia_duo_descriptions/meshes/Link8.STL" />
      </geometry>
    </collision>
  </link>
  <joint
    name="right_finger"
    type="fixed">
    <origin
      xyz="-0.0065308 0.013945 0.11382"
      rpy="1.5708 0 3.1416" />
    <parent
      link="Grasp_base" />
    <child
      link="Link8" />
    <axis
      xyz="0 0 1" />

  </joint>
</robot>
